Workbook

Sheet Candidatos E-26 ALC
A1: ID Candidato | B1: Municipio | C1: Departamento | D1: DIVIPOLA | E1: Cód | F1: Candidato | G1: Partido / Movimiento Político | H1: Votos | I1: Ganador
A2: COL-05045-001 | B2: Apartadó | C2: Antioquia | D2: 05045 | E2: 1 | F2: Adolfo Leon Tabares Gutierrez | G2: Movimiento Salvación Nacional | H2: 1238 | I2: No
A3: COL-05045-002 | B3: Apartadó | C3: Antioquia | D3: 05045 | E3: 2 | F3: Luis Gonzalo Giraldo Aguirre | G3: Agrupación Política en Marcha | H3: 146 | I3: No
A4: COL-05045-003 | B4: Apartadó | C4: Antioquia | D4: 05045 | E4: 3 | F4: John Jaime Urrea Chica | G4: Partido Colombia Justa Libres | H4: 541 | I4: No
A5: COL-05045-004 | B5: Apartadó | C5: Antioquia | D5: 05045 | E5: 4 | F5: Hector Rangel Palacios Rodriguez | G5: Unidos por la Vida | H5: 28317 | I5: Sí
A6: COL-05045-005 | B6: Apartadó | C6: Antioquia | D6: 05045 | E6: 5 | F6: Adolfo David Romero Benitez | G6: Partido Conservador Colombiano | H6: 21889 | I6: No
A7: COL-05045-006 | B7: Apartadó | C7: Antioquia | D7: 05045 | E7: 6 | F7: Luis Augusto Medina Pulgarin | G7: Partido Político Dignidad & Compromiso | H7: 774 | I7: No
A8: COL-05045-007 | B8: Apartadó | C8: Antioquia | D8: 05045 | E8: 7 | F8: Luis Enrique Teran Mosquera | G8: Partido Político Esperanza Democrática | H8: 352 | I8: No
A9: COL-05045-008 | B9: Apartadó | C9: Antioquia | D9: 05045 | E9: 8 | F9: Henry Cordoba Rivas | G9: Movimiento Político Colombia Humana | H9: 0 | I9: No
A10: COL-05045-009 | B10: Apartadó | C10: Antioquia | D10: 05045 | E10: 9 | F10: Jhon Fredis Cordoba Perea | G10: Partido Político Gente en Movimiento | H10: 0 | I10: No
A11: COL-05045-010 | B11: Apartadó | C11: Antioquia | D11: 05045 | E11: 10 | F11: Fredy Edison Largo Suarez | G11: Pacto Histórico | H11: 579 | I11: No
A12: COL-05045-011 | B12: Apartadó | C12: Antioquia | D12: 05045 | E12: 11 | F12: Ricardo Leon Camargo Ortiz | G12: Apartadó Vamos con Toda | H12: 0 | I12: No
A13: COL-63001-001 | B13: Armenia | C13: Quindío | D13: 63001 | E13: 1 | F13: German Laureano Ujueta Diago | G13: Movimiento Alianza Democrática Amplia | H13: 388 | I13: No
... A351: COL-50001-016 | B351: Villavicencio | C351: Meta | D351: 50001 | E351: 16 | F351: Irina Colette Salas Londoño | G351: Somos la Fuerza | H351: 40604 | I351: No

Sheet Redes Sociales
A1: ID Candidato | B1: Votos | C1: Municipio | D1: Candidato | E1: Partido / Movimiento Político | F1: Ganador | G1: gano | H1: Ausencia | I1: Ausencia_url | J1: Instagram | K1: X / Twitter | L1: TikTok | M1: Facebook
A2: COL-05045-004 | B2: =VLOOKUP(A2,'Candidatos E-26 ALC'!A5:I354,8,FALSE) -> 28317 | C2: Apartadó | D2: Hector Rangel Palacios Rodriguez | E2: Unidos por la Vida | F2: Sí | G2: 1 | J2: https://www.instagram.com/hectorrangelp/ | K2: https://x.com/HectorRangelPal | L2: https://www.tiktok.com/@hectorrangelp | M2: https://www.facebook.com/hectorrangelpalacios/?locale=es_LA
A3: COL-05045-005 | B3: =VLOOKUP(A3,'Candidatos E-26 ALC'!A6:I355,8,FALSE) -> 21889 | C3: Apartadó | D3: Adolfo David Romero Benitez | E3: Partido Conservador Colombiano | F3: No | G3: 0 | J3: https://www.instagram.com/adolforomerolider/ | K3: https://x.com/AdolfoRomeroB | M3: https://www.facebook.com/adolforomerob
A4: COL-05045-001 | B4: =VLOOKUP(A4,'Candidatos E-26 ALC'!A2:I351,8,FALSE) -> 1238 | C4: Apartadó | D4: Adolfo Leon Tabares Gutierrez | E4: Movimiento Salvación Nacional | F4: No | G4: 0
A5: COL-05045-006 | B5: =VLOOKUP(A5,'Candidatos E-26 ALC'!A7:I356,8,FALSE) -> 774 | C5: Apartadó | D5: Luis Augusto Medina Pulgarin | E5: Partido Político Dignidad & Compromiso | F5: No | G5: 0
A6: COL-05045-010 | B6: =VLOOKUP(A6,'Candidatos E-26 ALC'!A11:I360,8,FALSE) -> 579 | C6: Apartadó | D6: Fredy Edison Largo Suarez | E6: Pacto Histórico | F6: No | G6: 0
A7: COL-05045-003 | B7: =VLOOKUP(A7,'Candidatos E-26 ALC'!A4:I353,8,FALSE) -> 541 | C7: Apartadó | D7: John Jaime Urrea Chica | E7: Partido Colombia Justa Libres | F7: No | G7: 0
A8: COL-05045-007 | B8: =VLOOKUP(A8,'Candidatos E-26 ALC'!A8:I357,8,FALSE) -> 352 | C8: Apartadó | D8: Luis Enrique Teran Mosquera | E8: Partido Político Esperanza Democrática | F8: No | G8: 0
A9: COL-05045-002 | B9: =VLOOKUP(A9,'Candidatos E-26 ALC'!A3:I352,8,FALSE) -> 146 | C9: Apartadó | D9: Luis Gonzalo Giraldo Aguirre | E9: Agrupación Política en Marcha | F9: No | G9: 0
A10: COL-05045-008 | B10: =VLOOKUP(A10,'Candidatos E-26 ALC'!A9:I358,8,FALSE) -> 0 | C10: Apartadó | D10: Henry Cordoba Rivas | E10: Movimiento Político Colombia Humana | F10: No | G10: 0
A11: COL-05045-009 | B11: =VLOOKUP(A11,'Candidatos E-26 ALC'!A10:I359,8,FALSE) -> 0 | C11: Apartadó | D11: Jhon Fredis Cordoba Perea | E11: Partido Político Gente en Movimiento | F11: No | G11: 0
A12: COL-05045-011 | B12: =VLOOKUP(A12,'Candidatos E-26 ALC'!A12:I361,8,FALSE) -> 0 | C12: Apartadó | D12: Ricardo Leon Camargo Ortiz | E12: Apartadó Vamos con Toda | F12: No | G12: 0
A13: COL-63001-013 | B13: =VLOOKUP(A13,'Candidatos E-26 ALC'!A25:I374,8,FALSE) -> 35703 | C13: Armenia | D13: James Padilla Garcia | E13: Armenia con Más Oportunidades | F13: Sí | G13: 1 | J13: https://www.instagram.com/jamespadillag/ | K13: https://x.com/jamespadillag | L13: https://www.tiktok.com/@jamespadillag | M13: https://www.facebook.com/JamesPadillaGar/
A14: COL-63001-014 | B14: =VLOOKUP(A14,'Candidatos E-26 ALC'!A26:I375,8,FALSE) -> 26687 | C14: Armenia | D14: Jose Ignacio Rojas Sepulveda | E14: Armenia 2027 | F14: No | G14: 0 | J14: https://www.instagram.com/joseignarojas/ | L14: https://www.tiktok.com/@joseignarojas | M14: https://www.facebook.com/Joseignaciorojasoficial/
A15: COL-63001-003 | B15: =VLOOKUP(A15,'Candidatos E-26 ALC'!A15:I364,8,FALSE) -> 11674 | C15: Armenia | D15: Stefany Gomez Murillo | E15: Liderazgo Ciudadano | F15: No | G15: 0 | J15: https://www.instagram.com/stefanygomezarmenia/ | K15: https://x.com/StefanyGomezArm/with_replies | L15: https://www.tiktok.com/@stefanygomezarmenia | M15: https://www.facebook.com/stefanygomezarmenia
A16: COL-63001-010 | B16: =VLOOKUP(A16,'Candidatos E-26 ALC'!A22:I371,8,FALSE) -> 10996 | C16: Armenia | D16: Bryant Stiven Naranjo Raigoza | E16: Armenia - Partido de la U - Partido en Marcha | F16: No | G16: 0
A17: COL-63001-004 | B17: =VLOOKUP(A17,'Candidatos E-26 ALC'!A16:I365,8,FALSE) -> 9436 | C17: Armenia | D17: Alvaro Arias Velasquez | E17: Armenia Nos Mueve | F17: No | G17: 0
A18: COL-63001-007 | B18: =VLOOKUP(A18,'Candidatos E-26 ALC'!A19:I368,8,FALSE) -> 7569 | C18: Armenia | D18: Oscar Gomez Agudelo | E18: Movimiento Salvación Nacional | F18: No | G18: 0
A19: COL-63001-006 | B19: =VLOOKUP(A19,'Candidatos E-26 ALC'!A18:I367,8,FALSE) -> 5135 | C19: Armenia | D19: Mary Luz Ospina Garcia | E19: Partido Centro Democrático | F19: No | G19: 0
A20: COL-63001-009 | B20: =VLOOKUP(A20,'Candidatos E-26 ALC'!A21:I370,8,FALSE) -> 2516 | C20: Armenia | D20: Javier Andres Angulo Gutierrez | E20: Partido Político La Fuerza de la Paz | F20: No | G20: 0
A21: COL-63001-005 | B21: =VLOOKUP(A21,'Candidatos E-26 ALC'!A17:I366,8,FALSE) -> 1928 | C21: Armenia | D21: Orlando Mosquera Forero | E21: Partido Ecologista Colombiano | F21: No | G21: 0
A22: COL-63001-011 | B22: =VLOOKUP(A22,'Candidatos E-26 ALC'!A23:I372,8,FALSE) -> 1914 | C22: Armenia | D22: Hernan Felipe Jaramillo Duque | E22: Movimiento Político Fuerza Ciudadana | F22: No | G22: 0
A23: COL-63001-002 | B23: =VLOOKUP(A23,'Candidatos E-26 ALC'!A14:I363,8,FALSE) -> 1503 | C23: Armenia | D23: Nasser Ramirez Gutierrez | E23: Partido Político Gente en Movimiento | F23: No | G23: 0
A24: COL-63001-008 | B24: =VLOOKUP(A24,'Candidatos E-26 ALC'!A20:I369,8,FALSE) -> 983 | C24: Armenia | D24: Ivan Paez Baquero | E24: Nueva Fuerza Democrática | F24: No | G24: 0
A25: COL-63001-012 | B25: =VLOOKUP(A25,'Candidatos E-26 ALC'!A24:I373,8,FALSE) -> 698 | C25: Armenia | D25: Rolando Muñoz Torres | E25: Partido Político Esperanza Democrática | F25: No | G25: 0
A26: COL-63001-001 | B26: =VLOOKUP(A26,'Candidatos E-26 ALC'!A13:I362,8,FALSE) -> 388 | C26: Armenia | D26: German Laureano Ujueta Diago | E26: Movimiento Alianza Democrática Amplia | F26: No | G26: 0
A27: COL-68081-005 | B27: =VLOOKUP(A27,'Candidatos E-26 ALC'!A31:I380,8,FALSE) -> 72593 | C27: Barrancabermeja | D27: Jonathan Stivel Vasquez Gomez | E27: Escribamos un Nuevo Capítulo | F27: Sí | G27: 1 | J27: https://www.instagram.com/jonathanvasquezgomez/ | K27: https://x.com/Jsvasquezg | L27: https://www.tiktok.com/@jonathanvasquezgomez | M27: https://www.facebook.com/JonathanVasquezColombia
A28: COL-68081-006 | B28: =VLOOKUP(A28,'Candidatos E-26 ALC'!A32:I381,8,FALSE) -> 28025 | C28: Barrancabermeja | D28: Elkin David Bueno Altahona | E28: Gratitud por la Gente | F28: No | G28: 0 | J28: https://www.instagram.com/elkindavidbueno/ | K28: https://x.com/elkindavidbueno/with_replies | L28: https://www.tiktok.com/@elkin.david.bueno | M28: https://www.facebook.com/elkindavidbueno/?locale=es_LA
A29: COL-68081-003 | B29: =VLOOKUP(A29,'Candidatos E-26 ALC'!A29:I378,8,FALSE) -> 15779 | C29: Barrancabermeja | D29: Claudia Patricia Andrade Gonzalez | E29: Partido Colombia Renaciente | F29: No | G29: 0 | J29: https://www.instagram.com/claudiandradegonzalez/ | K29: https://x.com/Claudia1Andrade | L29: https://www.tiktok.com/@claudiaandradegonzalez | M29: https://www.facebook.com/Claudia.Andrade.2022/
A30: COL-68081-010 | B30: =VLOOKUP(A30,'Candidatos E-26 ALC'!A36:I385,8,FALSE) -> 2740 | C30: Barrancabermeja | D30: Jaime Enrique Peña Robles | E30: Movimiento Salvación Nacional | F30: No | G30: 0
A31: COL-68081-004 | B31: =VLOOKUP(A31,'Candidatos E-26 ALC'!A30:I379,8,FALSE) -> 1020 | C31: Barrancabermeja | D31: Edinson Ariel Diosa Taborda | E31: Movimiento Político Colombia Humana | F31: No | G31: 0
A32: COL-68081-002 | B32: =VLOOKUP(A32,'Candidatos E-26 ALC'!A28:I377,8,FALSE) -> 1000 | C32: Barrancabermeja | D32: Gustavo Adolfo de la Ossa Sanchez | E32: Transformando Territorio | F32: No | G32: 0
A33: COL-68081-007 | B33: =VLOOKUP(A33,'Candidatos E-26 ALC'!A33:I382,8,FALSE) -> 639 | C33: Barrancabermeja | D33: Rafael Leonardo Granados Cardenas | E33: Partido Ecologista Colombiano | F33: No | G33: 0
A34: COL-68081-009 | B34: =VLOOKUP(A34,'Candidatos E-26 ALC'!A35:I384,8,FALSE) -> 614 | C34: Barrancabermeja | D34: Jose Alexander Perdomo Sepulveda | E34: Nueva Fuerza Democrática | F34: No | G34: 0
A35: COL-68081-001 | B35: =VLOOKUP(A35,'Candidatos E-26 ALC'!A27:I376,8,FALSE) -> 411 | C35: Barrancabermeja | D35: Elcida Martinez Peinado | E35: Movimiento Político Fuerza Ciudadana | F35: No | G35: 0
A36: COL-68081-008 | B36: =VLOOKUP(A36,'Candidatos E-26 ALC'!A34:I383,8,FALSE) -> 361 | C36: Barrancabermeja | D36: Rafael Garces Barragan | E36: Partido Político Creemos | F36: No | G36: 0
A37: COL-68081-012 | B37: =VLOOKUP(A37,'Candidatos E-26 ALC'!A38:I387,8,FALSE) -> 133 | C37: Barrancabermeja | D37: Paul Enrique Solorzano Garcia | E37: Partido Político Dignidad & Compromiso | F37: No | G37: 0
A38: COL-68081-011 | B38: =VLOOKUP(A38,'Candidatos E-26 ALC'!A37:I386,8,FALSE) -> 68 | C38: Barrancabermeja | D38: Alvaro Perez Vides | E38: Partido Político Gente en Movimiento | F38: No | G38: 0
A39: COL-08001-002 | B39: =VLOOKUP(A39,'Candidatos E-26 ALC'!A40:I389,8,FALSE) -> 417644 | C39: Barranquilla | D39: Alejandro Char Chaljub | E39: Partido Cambio Radical | F39: Sí | G39: 1 | J39: https://www.instagram.com/alejandrocharch/ | K39: https://x.com/AlejandroChar | L39: https://www.tiktok.com/@alejandrocharch | M39: https://www.facebook.com/AlejandroCharCh
A40: COL-08001-005 | B40: =VLOOKUP(A40,'Candidatos E-26 ALC'!A43:I392,8,FALSE) -> 53144 | C40: Barranquilla | D40: Antonio Eduardo Bohorquez Collazos | E40: Partido Polo Democrático Alternativo | F40: No | G40: 0 | J40: https://www.instagram.com/antoniobohorquez_/ | K40: https://x.com/bohorquezesova | L40: https://www.tiktok.com/@antonio_bohorquez | M40: https://www.facebook.com/antonio.e.collazos/
...

Sheet Hoja1
B2: Candidatos | C2: USD | D2: Tiempo (min) | E2: Tiempo(hrs)
A3: TikTok | B3: 112 | C3: =B3*0.012 -> 1.344 | D3: =((60+35)/60)*B3 -> 177.33333 | E3: =D3/60 -> 2.9555556
A4: Facebook | B4: 123 | C4: =B4*0.241 -> 29.643 | D4: =((60+5)/60)*B4 -> 133.25 | E4: =D4/60 -> 2.2208333

Sheet Resumen por Municipio
A1: Municipio | B1: Departamento | C1: DIVIPOLA | D1: N° Candidatos | E1: Total Votos Candidatos | F1: Alcalde Electo | G1: Partido Ganador | H1: Votos Ganador
A2: Apartadó | B2: Antioquia | C2: 05045 | D2: 11 | E2: 53836 | F2: Hector Rangel Palacios Rodriguez | G2: Unidos por la Vida | H2: 28317
A3: Armenia | B3: Quindío | C3: 63001 | D3: 14 | E3: 117130 | F3: James Padilla Garcia | G3: Armenia con Más Oportunidades | H3: 35703
A4: Barrancabermeja | B4: Santander | C4: 68081 | D4: 12 | E4: 123383 | F4: Jonathan Stivel Vasquez Gomez | G4: Escribamos un Nuevo Capítulo | H4: 72593
A5: Barranquilla | B5: Atlántico | C5: 08001 | D5: 6 | E5: 510163 | F5: Alejandro Char Chaljub | G5: Partido Cambio Radical | H5: 417644
A6: Bello | B6: Antioquia | C6: 05049 | D6: 9 | E6: 148408 | F6: Yulieth Lorena Gonzalez Ospina | G6: Bello Nos Une | H6: 64022
A7: Bogotá D.C. | B7: Bogotá D.C. | C7: 11001 | D7: 9 | E7: 2906741 | F7: Carlos Fernando Galan Pachon | G7: Partido Nuevo Liberalismo | H7: 1499734
A8: Bucaramanga | B8: Santander | C8: 68001 | D8: 15 | E8: 247630 | F8: Jaime Andres Beltran Martinez | G8: Defendamos Bucaramanga | H8: 91418
A9: Buenaventura | B9: Valle del Cauca | C9: 76109 | D9: 16 | E9: 98753 | F9: Ligia del Carmen Cordoba Martinez | G9: Coalición Alcaldía de Buenaventura | H9: 42201
A10: Cali | B10: Valle del Cauca | C10: 76001 | D10: 10 | E10: 703975 | F10: Alvaro Alejandro Eder Garces | G10: Revivamos Cali | H10: 318656
A11: Cartagena | B11: Bolívar | C11: 13001 | D11: 12 | E11: 336038 | F11: Dumek Jose Turbay Paz | G11: Unidos para Avanzar | H11: 160548
A12: Cúcuta | B12: Norte de Santander | C12: 54001 | D12: 14 | E12: 297325 | F12: Jorge Enrique Acevedo Peñaloza | G12: Todos por Cúcuta | H12: 89753
A13: Dosquebradas | B13: Risaralda | C13: 66170 | D13: 5 | E13: 76219 | F13: Roberto Jimenez Naranjo | G13: Dosquebradas Visión de Ciudad | H13: 24279
... A34: Villavicencio | B34: Meta | C34: 50001 | D34: 16 | E34: 212549 | F34: Alexander Baquero Sanabria | G34: Recuperemos Villavo | H34: 70987

Sheet Población 2023 (DANE)
A1: # | B1: Municipio | C1: Departamento | D1: DIVIPOLA | E1: Población 2023 | F1: Fuente
A2: 1 | B2: Bogotá D.C. | C2: Bogotá D.C. | D2: 11001 | E2: 7181469 | F2: DANE – Proyecciones de población post-CNPV 2018
A3: 2 | B3: Medellín | C3: Antioquia | D3: 05001 | E3: 2700453 | F3: DANE – Proyecciones de población post-CNPV 2018
A4: 3 | B4: Cali | C4: Valle del Cauca | D4: 76001 | E4: 2252616 | F4: DANE – Proyecciones de población post-CNPV 2018
A5: 4 | B5: Barranquilla | C5: Atlántico | D5: 08001 | E5: 1274250 | F5: DANE – Proyecciones de población post-CNPV 2018
A6: 5 | B6: Cartagena | C6: Bolívar | D6: 13001 | E6: 1081577 | F6: DANE – Proyecciones de población post-CNPV 2018
A7: 6 | B7: Cúcuta | C7: Norte de Santander | D7: 54001 | E7: 773239 | F7: DANE – Proyecciones de población post-CNPV 2018
A8: 7 | B8: Soledad | C8: Atlántico | D8: 08433 | E8: 764068 | F8: DANE – Proyecciones de población post-CNPV 2018
A9: 8 | B9: Soacha | C9: Cundinamarca | D9: 25754 | E9: 743573 | F9: DANE – Proyecciones de población post-CNPV 2018
A10: 9 | B10: Ibagué | C10: Tolima | D10: 73001 | E10: 581130 | F10: DANE – Proyecciones de población post-CNPV 2018
A11: 10 | B11: Bucaramanga | C11: Santander | D11: 68001 | E11: 541607 | F11: DANE – Proyecciones de población post-CNPV 2018
A12: 11 | B12: Santa Marta | C12: Magdalena | D12: 47001 | E12: 527949 | F12: DANE – Proyecciones de población post-CNPV 2018
A13: 12 | B13: Bello | C13: Antioquia | D13: 05049 | E13: 524360 | F13: DANE – Proyecciones de población post-CNPV 2018
... A34: 33 | B34: Piedecuesta | C34: Santander | D34: 68547 | E34: 196084 | F34: DANE – Proyecciones de población post-CNPV 2018
B35: TOTAL | E35: =SUM(E2:E34) -> 25886112
A37: Fuente: Proyecciones de población con actualización post COVID-19, calculadas con base en el Censo Nacional de Población y Vivienda (CNPV) 2018. DANE, Colombia.
